Workbook

Sheet Cover Page
C10: ceda logo
C16: MICRO FINANCE APPRAISAL TOOL
C18: REPORT CONTENTS:
C19: Promoter Details
C20: Assesment
C21: Financials
C22: Result

Sheet Promoter Details
A1: APPENDIX 1 | L1: Married
A2: Promoter Details | L2: Separated
L3: Divorced
A4: 1. Applicant Background Info | L4: Widowed
B5: 1.1 Name of the Applicant | C5: BEAUTY IPOPENG BBATHULENG | L5: Single
B6: 1.2 Name of the Group | C6: THAPAMA
B7: 1.3 Omang Number | C7: 084421104' | L7: <1 Year
B8: 1.4 Gender | C8: Female | L8: 1-2 Years
B9: 1.5 Date of Birth | C9: 25/12/1975 | L9: >3 Years
B10: 1.6 Age at application | C10: 45
B11: 1.7 Marital Status | C11: Single
B13: 1.8 Postal Address | C13: P O Box 50 LEKHUBU
B14: 1.9 Physical Address | C14: LEKHUBU WARD, OTSE | L14: Non
B15: 1.10 Years at Physical Address | C15: >3 Years | L15: PSLE
B16: 1.11 Contact Details | C16: 71416409 | L16: JCE
L17: BGCSE, GCE, IGCSE
A18: 2. Education and Experience | L18: Certificate
B19: 2.1 Highest Education Level | C19: JCE | L19: Diploma
B20: 2.2 Training related to Business Concept | C20: MABOGO DINKU PREFUNDING TRAINING | L20: Degree
B21: 2.3 Experience in Business (Related to current concept) | C21: 10 YEARS BUSINESS EXPERIENCE | L21: Non-Formal Education
L22: Others (Specify)
A23: 3. Business Description
B24: 3.1 Business Sector | C24: Services
B25: 3.2 Business Description and Product Offering | C25: STREET VENDOR | L25: Agribusiness
B26: 3.3 Business status (Start up/expansion) | C26: Start-up | L26: Services
B27: 3.4 Financing Type | C27: Working Capital
B28: 3.5 Business Location | C28: OTSE
B29: 3.6 Number of Years Operating | C29: >3 Years | L29: Asset Finance
B30: 3.7 Existing Employment | C30: 1 | L30: Working Capital
B31: 3.8 Additional Employment | C31: 0 | L31: Asset & Working Capital
B32: 3.9 Total Employed (Projected) | C32: =SUM(C30:C31) -> 1
L33: Male
A34: 4. Loan Details | L34: Female
B35: 4.1 Group Contribution | C35: 6700
B36: 4.2 Group Loan Limit | C36: =C35*10 -> 67000 | L36: Monthly
B37: 4.3 Individual Contribution | C37: 500 | L37: Fortnightly
B38: 4.4 Individual Loan Limit | C38: =C37*10 -> 5000 | L38: Weekly
B40: 4.5 Loan Purpose | C40: WORKING CAPITAL | L40: Start-up
B41: 4.6 Loan Amount | C41: 5000 | L41: Expansion
B42: 4.7 Interest Rate | C42: 0.05
...

Sheet Assesment
A1: APPENDIX 2
A3: 1.1 Credit Evaluation | G3: Key:
A4: Component | C4: Variable | D4: Additional Comments | G4: 5 | H4: Excellent
A5: Is the promoter servicing other loans well? | C5: N/A | D5: The are no loans | G5: 4 | H5: very good
A6: Is the promoter listed on the ITC/Credit Buruea? | C6: No | D6: The promoter is not listed on ITC & MBF | G6: 3 | H6: good
G7: 2 | H7: fair | I7: 0
A8: 1.2 Management Assesment | G8: 1 | H8: poor | I8: 1
A9: Component | C9: Variable | D9: Additional comments | G9: 0 | H9: verypoor | I9: 2
A10: Education/Experience related to the industry | C10: 4 | D10: The promoter has attended Mabogo Dinku pre funding training. | I10: 3
A11: Skills Related to running the business | C11: 3 | D11: She has adequate business experience. Has previously ran a poultry business thus has skills in sales as well as business management. | I11: 4
A12: Promoter capable of running the business | C12: 3 | D12: The promoter is physically and mentally fit to run the business. | I12: 5
A13: Does the business have the right personel to compete | C13: 3 | D13: She is highly competent.
A14: Promoter's personal committment to business(personal investments) | C14: 4 | D14: She was previously assisted with a loan of P7000 to establish a poultry business. Currently she wants to start up a street vendor business. | I14: Yes
I15: No
A16: 1.3 Market Assesment | I16: N/A
A17: Component | C17: Variable | D17: Additional Comments
A18: Is there a gap in the market ? | C18: 4 | D18: There is gap in the market for the promoter's services .
A19: Are there potential buyers for this product/service ? | C19: 3 | D19: There are potential buyers for the products offered.
A20: Is the business concept well defined and sustainable ? | C20: 3 | D20: The business concept is well defined and sustainable.
A21: Does the business have competive advantage ? | C21: 3 | D21: The promoter's competitive advantage is that the location of the business is highly visible.
A22: Will the population density and demograpghics support the business? | C22: 4 | D22: The population density of Otse and surrounding villages is adequate to sustain the business.
A24: 1.4 Operational Effeciency
A25: Component | C25: Variable | D25: Additional Comments
A26: Is the business to sensitive to changes in purchase and selling price ? | C26: 3 | D26: The business is responsive to changes in purchasing prices.
A27: Is the location suitable for the business? | C27: 3 | D27: The location is safe and suitable for the project. There are no cases of theft or break-ins.
A28: Are all the necessary resources for offering service/ product available? | C28: 3 | D28: The promoter has a shortage of stock.
A29: Is the business able to deal with its challenges | B29: Is the business able to deal with its major threats | C29: 3 | D29: The business is able to deal with its challenges.

Sheet Financials
A1: APPENDIX 3 | D1: Business Income Statement | G1: HouseholdCashflow | I1: BalanceSheet
A3: Business Income Statement
B4: Existing Business | D4: Start Up Business
B5: Actual | C5: Actual | D5: Forecast | E5: Forecast | F5: Forecast
A6: Total Sales | B6: Monthly | C6: Annually | D6: Weekly | E6: Monthly | F6: Annually
A7: Sales Revenue | B7: 7000 | C7: =B7*12 -> 84000 | D7: =B7/4 -> 1750 | E7: =D7*4 -> 7000 | F7: =E7*12 -> 84000
A8: Sales Cost | B8: 5000 | C8: 60000 | D8: =B8/4 -> 1250 | E8: =D8*4 -> 5000 | F8: =E8*12 -> 60000
A9: Total Cashflow | B9: =IFERROR(B7-B8,"") -> 2000 | C9: =IFERROR(C7-C8,"") -> 24000 | D9: =IFERROR(D7-D8,"") -> 500 | E9: =IFERROR(E7-E8,"") -> 2000 | F9: =IFERROR(F7-F8,"") -> 24000
B11: Actual | C11: Actual | D11: Forecast | E11: Forecast | F11: Forecast
A12: Operating Expenses | B12: =B6 -> Monthly | C12: =C6 -> Annually | D12: =D6 -> Weekly | E12: Monthly | F12: Annually
A13: Wages and Salaries | E13: =D13*4 -> 0 | F13: =E13*12 -> 0
A14: Rent | E14: =D14*4 -> 0 | F14: =E14*12 -> 0
A15: Water | E15: =D15*4 -> 0 | F15: =E15*12 -> 0
A16: Electricity | E16: =D16*4 -> 0 | F16: =E16*12 -> 0
A17: Transportation/Fuel | B17: 350 | C17: 4200 | D17: =B17/4 -> 87.5 | E17: =D17*4 -> 350 | F17: =E17*12 -> 4200
A18: Licencing/Taxes | B18: 100 | C18: 1200 | D18: 25 | E18: =D18*4 -> 100 | F18: =E18*12 -> 1200
A19: Insurance | E19: =D19*4 -> 0 | F19: =E19*12 -> 0
A20: Other Expenses | E20: =D20*4 -> 0 | F20: =E20*12 -> 0
A21: Other Expenses | E21: =D21*4 -> 0 | F21: =E21*12 -> 0
A22: Other Expenses | E22: =D22*4 -> 0 | F22: =E22*12 -> 0
A23: Other Expenses | E23: =D23*4 -> 0 | F23: =E23*12 -> 0
A24: Other Expenses | E24: =D24*4 -> 0 | F24: =E24*12 -> 0
A25: Liabilities (Loans) | E25: =D25*4 -> 0 | F25: =E25*12 -> 0
A26: Total Operating Expenses | B26: =SUM(B13:B25) -> 450 | C26: =SUM(C13:C25) -> 5400 | D26: =SUM(D13:D25) -> 112.5 | E26: =SUM(E13:E25) -> 450 | F26: =SUM(F13:F25) -> 5400
B28: Actual | C28: Actual | D28: Forecast | E28: Forecast | F28: Forecast
A29: Net Business Cashflow | B29: =B6 -> Monthly | C29: =C6 -> Annually | D29: =D6 -> Weekly | E29: Monthly | F29: Annually
B30: =B9-B26 -> 1550 | C30: =C9-C26 -> 18600 | D30: =D9-D26 -> 387.5 | E30: =E9-E26 -> 1550 | F30: =F9-F26 -> 18600
A36: Household Cashflow
B38: Actual | C38: Actual | D38: Forecast | E38: Forecast | F38: Forecast
B39: =B6 -> Monthly | C39: =C6 -> Annually | D39: =D6 -> Weekly | E39: Monthly | F39: Annually
A40: Net Business Cashflow | B40: =B30 -> 1550 | C40: =C30 -> 18600 | D40: =D30 -> 387.5 | E40: =E30 -> 1550 | F40: =F30 -> 18600
B42: Actual | C42: Actual | D42: Forecast | E42: Forecast | F42: Forecast
A43: Household Income | B43: =B6 -> Monthly | C43: =C6 -> Annually | D43: =D6 -> Weekly | E43: Monthly | F43: Annually
A44: Spouse | D44: =B44/4 -> 0 | E44: =D44*4 -> 0 | F44: =E44*12 -> 0
A45: Children | D45: =B45/4 -> 0 | E45: =D45*4 -> 0 | F45: =E45*12 -> 0
A46: Rent | D46: =B46/4 -> 0 | E46: =D46*4 -> 0 | F46: =E46*12 -> 0
A47: Transfers | D47: =B47/4 -> 0 | E47: =D47*4 -> 0 | F47: =E47*12 -> 0
A48: Other | B48: 1000 | C48: 12000 | D48: =B48/4 -> 250 | E48: =D48*4 -> 1000 | F48: =E48*12 -> 12000
A49: Total Household Income | B49: =SUM(B40,B44:B48) -> 2550 | C49: =SUM(C40,C44:C48) -> 30600 | D49: =SUM(D40,D44:D48) -> 637.5 | E49: =SUM(E40,E44:E48) -> 2550 | F49: =SUM(F40,F44:F48) -> 30600
B51: Actual | C51: Actual | D51: Forecast | E51: Forecast | F51: Forecast
...

Sheet Scorecard
A2: Management Assesment
A3: Component | B3: Rating | C3: Weight | D3: Score
A4: Education/Experience related to the industry | B4: =Assesment!C10 -> 4 | C4: 0.05 | D4: =B4*$C$4 -> 0.2 | G4: 0 | I4: 1 | K4: 2 | M4: 3 | O4: 4 | Q4: 5
A5: Skills Related to running the business | B5: =Assesment!C11 -> 3 | C5: 0.07 | D5: =B5*$C$4 -> 0.15 | G5: 0 | I5: 1 | K5: 2 | M5: 3 | O5: 4 | Q5: 5
A6: Promoter capable of running the business | B6: =Assesment!C12 -> 3 | C6: 0.1 | D6: =B6*$C$4 -> 0.15 | G6: 0 | I6: 1 | K6: 2 | M6: 3 | O6: 4 | Q6: 5
A7: Does the business have the right personel to compete | B7: =Assesment!C13 -> 3 | C7: 0.04 | D7: =B7*$C$4 -> 0.15 | G7: 0 | I7: 1 | K7: 2 | M7: 3 | O7: 4 | Q7: 5
A8: Promoter's personal committment to business(personal investments) | B8: =Assesment!C14 -> 4 | C8: 0.04 | D8: =B8*$C$4 -> 0.2 | G8: 0 | I8: 1 | K8: 2 | M8: 3 | O8: 4 | Q8: 5
C9: =SUM(C4:C8) -> 0.3 | D9: =SUM(D4:D8) -> 0.85 | E9: =D9/1.25*C9 -> 0.204
A10: Market Assesment
A11: Component | B11: Rating | C11: Weight | D11: Score
A12: Is there a gap in the market ? | B12: =Assesment!C18 -> 4 | C12: 0.06 | D12: =B12*$C$12 -> 0.24 | G12: 0 | I12: 1 | K12: 2 | M12: 3 | O12: 4 | Q12: 5
A13: Are there potential buyers for this product/service ? | B13: =Assesment!C19 -> 3 | C13: 0.06 | D13: =B13*$C$12 -> 0.18 | G13: 0 | I13: 1 | K13: 2 | M13: 3 | O13: 4 | Q13: 5
A14: Is the business concept well defined and sustainable ? | B14: =Assesment!C20 -> 3 | C14: 0.07 | D14: =B14*$C$12 -> 0.18 | G14: 0 | I14: 1 | K14: 2 | M14: 3 | O14: 4 | Q14: 5
A15: Does the business have competive advantage ? | B15: =Assesment!C21 -> 3 | C15: 0.04 | D15: =B15*$C$12 -> 0.18 | G15: 0 | I15: 1 | K15: 2 | M15: 3 | O15: 4 | Q15: 5
A16: Will the population density and demograpghics support the business ? | B16: =Assesment!C22 -> 4 | C16: 0.02 | D16: =B16*$C$12 -> 0.24 | G16: 0 | I16: 1 | K16: 2 | M16: 3 | O16: 4 | Q16: 5
C17: =SUM(C12:C16) -> 0.25 | D17: =SUM(D12:D16) -> 1.02 | E17: =D17/1.5*C17 -> 0.17
A18: Operational Effeciency
A19: Component | B19: Rating | C19: Weight | D19: Score
A20: How sensitive is the business to changes in purchase and Selling price ? | B20: =Assesment!C26 -> 3 | C20: 0.06 | D20: =B20*$C$20 -> 0.18 | G20: 0 | I20: 1 | K20: 2 | M20: 3 | O20: 4 | Q20: 5
A21: Is the location suitable for the business? | B21: =Assesment!C27 -> 3 | C21: 0.03 | D21: =B21*$C$20 -> 0.18 | G21: 0 | I21: 1 | K21: 2 | M21: 3 | O21: 4 | Q21: 5
A22: Are all the necessary resources for offering service/ product available? | B22: =Assesment!C28 -> 3 | C22: 0.08 | D22: =B22*$C$20 -> 0.18 | G22: 0 | I22: 1 | K22: 2 | M22: 3 | O22: 4 | Q22: 5
A23: Is the business able to deal with its challenges | B23: =Assesment!C29 -> 3 | C23: 0.03 | D23: =B23*$C$20 -> 0.18 | G23: 0 | I23: 1 | K23: 2 | M23: 3 | O23: 4 | Q23: 5
C24: =SUM(C20:C23) -> 0.2 | D24: =SUM(D20:D23) -> 0.72 | E24: =D24/1.2*C24 -> 0.12
A25: Financial Assesment
A26: Component | B26: Rating | C26: Weight | D26: Score
A27: Is the Business profitable | B27: =IF(Financials!$E$30>0,5,0) -> 5 | C27: 0.03 | D27: =B27*C27 -> 0.15 | G27: Yes | H27: 5 | I27: No | J27: 0
A28: Is the cashflow sufficient to cover installment & still leave profit | B28: =IF(Financials!$E$70>0,5,0) -> 5 | C28: 0.08 | D28: =B28*C28 -> 0.4 | G28: Yes | H28: 5 | I28: No | J28: 0
A29: Is the Debt Burden Ratio within CEDA guidelines | B29: =IF(Financials!$E$74<50,5,0) -> 5 | C29: 0.04 | D29: =B29*C29 -> 0.2 | G29: Yes | H29: 5 | I29: No | J29: 0
C30: =SUM(C27:C29) -> 0.15 | D30: =SUM(D27:D29) -> 0.75 | E30: =D30/0.75*C30 -> 0.15
A31: Credit Evaluation
A32: Component | B32: Rating | C32: Weight | D32: Score
A33: Is the promoter servicing other loans well | B33: =IF(Assesment!C5="Yes",5, IF(Assesment!C5="N/A",5, IF(Assesment!C5="No",0,0))) -> 5 | C33: 0.04 | D33: =B33*$C$33 -> 0.2 | G33: Yes | H33: 5 | I33: No | J33: 0
A34: Is the promoter listed on the ITC/Credit Buruea | B34: =IF(Assesment!C6="No",5,0) -> 5 | C34: 0.06 | D34: =B34*$C$33 -> 0.2 | G34: Yes | H34: 5 | I34: No | J34: 0
C35: =SUM(C33:C34) -> 0.1 | D35: =SUM(D33:D34) -> 0.4 | E35: =D35/0.4*C35 -> 0.1

Sheet Result
A1: APPENDIX 4
B2: SCORECARD SUMMARY
C3: Weight | D3: Score
B4: Management Assesment | C4: =Scorecard!C9 -> 0.3 | D4: =Scorecard!E9 -> 0.204
B5: Market Assesment | C5: =Scorecard!C17 -> 0.25 | D5: =Scorecard!E17 -> 0.17
B6: Operational Effeciency | C6: =Scorecard!C24 -> 0.2 | D6: =Scorecard!E24 -> 0.12
B7: Financial Assesment | C7: =Scorecard!C30 -> 0.15 | D7: =Scorecard!E30 -> 0.15
B8: Credit Evaluation | C8: =Scorecard!C35 -> 0.1 | D8: =Scorecard!E35 -> 0.1
B9: Total | C9: =SUM(C4:C8) -> 1 | D9: =SUM(D4:D8) -> 0.744
B12: Debt Burden Ratio | C12: =Financials!E74 -> 0.4334556 | D12: =IF(C12>=50%,"Exceeded Limit","Within Limit") -> Within Limit
B13: Net Profit | C13: =IFERROR(Financials!$E$30,"") -> 1550 | D13: =IF(C13>0,"Profitable","Not Profitable") -> Profitable
B14: Cash Flow | C14: =IF(Financials!$E$70>0,"Positive","Negative") -> Positive
B15: ITC and Credit Bureau | C15: =IF(Assesment!C6="Yes","Recommend Rejection","Not Listed") -> Not Listed
B17: PE's Comments:
B18: Recommend approval
B21: Recommendation:
B22: Approval
B25: Offer Conditions
B26: Loan Amount: BWP 5000.00
B27: Interest Rate: 3,75%
B28: Repayment period: 12 months
B29: Installment: BWP 432,29
B30: Frequency: Monthly
B31: Due Date of Installment: 30/01/2021
B33: Signatories
B34: Prepared By | D34: MF Coordinator | G34: Regional Manager
B36: ……………………………………….. | D36: ……………………………………….. | G36: ………………………………………..
B38: Comments | D38: Comments | G38: Comments
B40: ……………………………………….. | D40: ……………………………………….. | G40: ………………………………………..
